<?xml version="1.0" encoding="UTF-8"?>
<testng-results ignored="0" total="6" passed="0" failed="6" skipped="0">
  <reporter-output>
  </reporter-output>
  <suite started-at="2023-12-01T16:03:57 IST" name="Default suite" finished-at="2023-12-01T16:04:16 IST" duration-ms="19823">
    <groups>
    </groups>
    <test started-at="2023-12-01T16:03:57 IST" name="Default test" finished-at="2023-12-01T16:04:16 IST" duration-ms="19823">
      <class name="Tests.LoginTest">
        <test-method is-config="true" signature="InitalizeExtentReport()[pri:0, instance:Tests.LoginTest@38aa816f]" started-at="2023-12-01T16:03:56 IST" name="InitalizeExtentReport" finished-at="2023-12-01T16:03:57 IST" duration-ms="340" status="PASS">
          <reporter-output>
          </reporter-output>
        </test-method> <!-- InitalizeExtentReport -->
        <test-method is-config="true" signature="getnameMethod(org.testng.ITestContext)[pri:0, instance:Tests.LoginTest@38aa816f]" started-at="2023-12-01T16:03:57 IST" name="getnameMethod" finished-at="2023-12-01T16:03:57 IST" duration-ms="12" status="PASS">
          <params>
            <param index="0">
              <value>
                <![CDATA[org.testng.TestRunner@57bdceaa]]>
              </value>
            </param>
          </params>
          <reporter-output>
          </reporter-output>
        </test-method> <!-- getnameMethod -->
        <test-method is-config="true" signature="setUp()[pri:0, instance:Tests.LoginTest@38aa816f]" started-at="2023-12-01T16:03:57 IST" name="setUp" finished-at="2023-12-01T16:04:00 IST" duration-ms="3327" status="PASS">
          <reporter-output>
          </reporter-output>
        </test-method> <!-- setUp -->
        <test-method signature="testLogin(java.lang.String,java.lang.String,java.lang.String)[pri:1, instance:Tests.LoginTest@38aa816f]" started-at="2023-12-01T16:04:01 IST" name="testLogin" data-provider="testdata" finished-at="2023-12-01T16:04:06 IST" duration-ms="4991" status="FAIL">
          <params>
            <param index="0">
              <value>
                <![CDATA[karthick1234554322@gmail.com]]>
              </value>
            </param>
            <param index="1">
              <value>
                <![CDATA["1234554321"]]>
              </value>
            </param>
            <param index="2">
              <value>
                <![CDATA[fail]]>
              </value>
            </param>
          </params>
          <exception class="java.lang.AssertionError">
            <message>
              <![CDATA[Login was unsuccessful. Error message is present.]]>
            </message>
            <full-stacktrace>
              <![CDATA[java.lang.AssertionError: Login was unsuccessful. Error message is present.
at org.testng.Assert.fail(Assert.java:110)
at Pages.LoginPage.login(LoginPage.java:40)
at Tests.LoginTest.testLogin(LoginTest.java:18)
at java.base/jdk.internal.reflect.DirectMethodHandleAccessor.invoke(DirectMethodHandleAccessor.java:104)
at java.base/java.lang.reflect.Method.invoke(Method.java:578)
at org.testng.internal.invokers.MethodInvocationHelper.invokeMethod(MethodInvocationHelper.java:139)
at org.testng.internal.invokers.TestInvoker.invokeMethod(TestInvoker.java:677)
at org.testng.internal.invokers.TestInvoker.invokeTestMethod(TestInvoker.java:221)
at org.testng.internal.invokers.MethodRunner.runInSequence(MethodRunner.java:50)
at org.testng.internal.invokers.TestInvoker$MethodInvocationAgent.invoke(TestInvoker.java:969)
at org.testng.internal.invokers.TestInvoker.invokeTestMethods(TestInvoker.java:194)
at org.testng.internal.invokers.TestMethodWorker.invokeTestMethods(TestMethodWorker.java:148)
at org.testng.internal.invokers.TestMethodWorker.run(TestMethodWorker.java:128)
at java.base/java.util.ArrayList.forEach(ArrayList.java:1511)
at org.testng.TestRunner.privateRun(TestRunner.java:829)
at org.testng.TestRunner.run(TestRunner.java:602)
at org.testng.SuiteRunner.runTest(SuiteRunner.java:437)
at org.testng.SuiteRunner.runSequentially(SuiteRunner.java:431)
at org.testng.SuiteRunner.privateRun(SuiteRunner.java:391)
at org.testng.SuiteRunner.run(SuiteRunner.java:330)
at org.testng.SuiteRunnerWorker.runSuite(SuiteRunnerWorker.java:52)
at org.testng.SuiteRunnerWorker.run(SuiteRunnerWorker.java:95)
at org.testng.TestNG.runSuitesSequentially(TestNG.java:1256)
at org.testng.TestNG.runSuitesLocally(TestNG.java:1176)
at org.testng.TestNG.runSuites(TestNG.java:1099)
at org.testng.TestNG.run(TestNG.java:1067)
at org.testng.remote.AbstractRemoteTestNG.run(AbstractRemoteTestNG.java:115)
at org.testng.remote.RemoteTestNG.initAndRun(RemoteTestNG.java:251)
at org.testng.remote.RemoteTestNG.main(RemoteTestNG.java:77)
]]>
            </full-stacktrace>
          </exception> <!-- java.lang.AssertionError -->
          <reporter-output>
          </reporter-output>
        </test-method> <!-- testLogin -->
        <test-method is-config="true" signature="generateTestStatus(java.lang.reflect.Method,org.testng.ITestResult)[pri:0, instance:Tests.LoginTest@38aa816f]" started-at="2023-12-01T16:04:06 IST" name="generateTestStatus" finished-at="2023-12-01T16:04:06 IST" duration-ms="11" status="PASS">
          <params>
            <param index="0">
              <value>
                <![CDATA[public void Tests.LoginTest.testLogin(java.lang.String,java.lang.String,java.lang.String)]]>
              </value>
            </param>
            <param index="1">
              <value>
                <![CDATA[[TestResult name=testLogin status=FAILURE method=LoginTest.testLogin(java.lang.String,java.lang.String,java.lang.String)[pri:1, instance:Tests.LoginTest@38aa816f] output={null}]]]>
              </value>
            </param>
          </params>
          <reporter-output>
          </reporter-output>
        </test-method> <!-- generateTestStatus -->
        <test-method signature="testLogin(java.lang.String,java.lang.String,java.lang.String)[pri:1, instance:Tests.LoginTest@38aa816f]" started-at="2023-12-01T16:04:06 IST" name="testLogin" data-provider="testdata" finished-at="2023-12-01T16:04:08 IST" duration-ms="1723" status="FAIL">
          <params>
            <param index="0">
              <value>
                <![CDATA[karthick1234554323@gmail.com]]>
              </value>
            </param>
            <param index="1">
              <value>
                <![CDATA["1234554321"]]>
              </value>
            </param>
            <param index="2">
              <value>
                <![CDATA[fail]]>
              </value>
            </param>
          </params>
          <exception class="java.lang.AssertionError">
            <message>
              <![CDATA[Login was unsuccessful. Error message is present.]]>
            </message>
            <full-stacktrace>
              <![CDATA[java.lang.AssertionError: Login was unsuccessful. Error message is present.
at org.testng.Assert.fail(Assert.java:110)
at Pages.LoginPage.login(LoginPage.java:40)
at Tests.LoginTest.testLogin(LoginTest.java:18)
at java.base/jdk.internal.reflect.DirectMethodHandleAccessor.invoke(DirectMethodHandleAccessor.java:104)
at java.base/java.lang.reflect.Method.invoke(Method.java:578)
at org.testng.internal.invokers.MethodInvocationHelper.invokeMethod(MethodInvocationHelper.java:139)
at org.testng.internal.invokers.TestInvoker.invokeMethod(TestInvoker.java:677)
at org.testng.internal.invokers.TestInvoker.invokeTestMethod(TestInvoker.java:221)
at org.testng.internal.invokers.MethodRunner.runInSequence(MethodRunner.java:50)
at org.testng.internal.invokers.TestInvoker$MethodInvocationAgent.invoke(TestInvoker.java:969)
at org.testng.internal.invokers.TestInvoker.invokeTestMethods(TestInvoker.java:194)
at org.testng.internal.invokers.TestMethodWorker.invokeTestMethods(TestMethodWorker.java:148)
at org.testng.internal.invokers.TestMethodWorker.run(TestMethodWorker.java:128)
at java.base/java.util.ArrayList.forEach(ArrayList.java:1511)
at org.testng.TestRunner.privateRun(TestRunner.java:829)
at org.testng.TestRunner.run(TestRunner.java:602)
at org.testng.SuiteRunner.runTest(SuiteRunner.java:437)
at org.testng.SuiteRunner.runSequentially(SuiteRunner.java:431)
at org.testng.SuiteRunner.privateRun(SuiteRunner.java:391)
at org.testng.SuiteRunner.run(SuiteRunner.java:330)
at org.testng.SuiteRunnerWorker.runSuite(SuiteRunnerWorker.java:52)
at org.testng.SuiteRunnerWorker.run(SuiteRunnerWorker.java:95)
at org.testng.TestNG.runSuitesSequentially(TestNG.java:1256)
at org.testng.TestNG.runSuitesLocally(TestNG.java:1176)
at org.testng.TestNG.runSuites(TestNG.java:1099)
at org.testng.TestNG.run(TestNG.java:1067)
at org.testng.remote.AbstractRemoteTestNG.run(AbstractRemoteTestNG.java:115)
at org.testng.remote.RemoteTestNG.initAndRun(RemoteTestNG.java:251)
at org.testng.remote.RemoteTestNG.main(RemoteTestNG.java:77)
]]>
            </full-stacktrace>
          </exception> <!-- java.lang.AssertionError -->
          <reporter-output>
          </reporter-output>
        </test-method> <!-- testLogin -->
        <test-method is-config="true" signature="generateTestStatus(java.lang.reflect.Method,org.testng.ITestResult)[pri:0, instance:Tests.LoginTest@38aa816f]" started-at="2023-12-01T16:04:08 IST" name="generateTestStatus" finished-at="2023-12-01T16:04:08 IST" duration-ms="3" status="PASS">
          <params>
            <param index="0">
              <value>
                <![CDATA[public void Tests.LoginTest.testLogin(java.lang.String,java.lang.String,java.lang.String)]]>
              </value>
            </param>
            <param index="1">
              <value>
                <![CDATA[[TestResult name=testLogin status=FAILURE method=LoginTest.testLogin(java.lang.String,java.lang.String,java.lang.String)[pri:1, instance:Tests.LoginTest@38aa816f] output={null}]]]>
              </value>
            </param>
          </params>
          <reporter-output>
          </reporter-output>
        </test-method> <!-- generateTestStatus -->
        <test-method signature="testLogin(java.lang.String,java.lang.String,java.lang.String)[pri:1, instance:Tests.LoginTest@38aa816f]" started-at="2023-12-01T16:04:08 IST" name="testLogin" data-provider="testdata" finished-at="2023-12-01T16:04:10 IST" duration-ms="2096" status="FAIL">
          <params>
            <param index="0">
              <value>
                <![CDATA[karthick1234554324@gmail.com]]>
              </value>
            </param>
            <param index="1">
              <value>
                <![CDATA["1234554321"]]>
              </value>
            </param>
            <param index="2">
              <value>
                <![CDATA[fail]]>
              </value>
            </param>
          </params>
          <exception class="java.lang.AssertionError">
            <message>
              <![CDATA[Login was unsuccessful. Error message is present.]]>
            </message>
            <full-stacktrace>
              <![CDATA[java.lang.AssertionError: Login was unsuccessful. Error message is present.
at org.testng.Assert.fail(Assert.java:110)
at Pages.LoginPage.login(LoginPage.java:40)
at Tests.LoginTest.testLogin(LoginTest.java:18)
at java.base/jdk.internal.reflect.DirectMethodHandleAccessor.invoke(DirectMethodHandleAccessor.java:104)
at java.base/java.lang.reflect.Method.invoke(Method.java:578)
at org.testng.internal.invokers.MethodInvocationHelper.invokeMethod(MethodInvocationHelper.java:139)
at org.testng.internal.invokers.TestInvoker.invokeMethod(TestInvoker.java:677)
at org.testng.internal.invokers.TestInvoker.invokeTestMethod(TestInvoker.java:221)
at org.testng.internal.invokers.MethodRunner.runInSequence(MethodRunner.java:50)
at org.testng.internal.invokers.TestInvoker$MethodInvocationAgent.invoke(TestInvoker.java:969)
at org.testng.internal.invokers.TestInvoker.invokeTestMethods(TestInvoker.java:194)
at org.testng.internal.invokers.TestMethodWorker.invokeTestMethods(TestMethodWorker.java:148)
at org.testng.internal.invokers.TestMethodWorker.run(TestMethodWorker.java:128)
at java.base/java.util.ArrayList.forEach(ArrayList.java:1511)
at org.testng.TestRunner.privateRun(TestRunner.java:829)
at org.testng.TestRunner.run(TestRunner.java:602)
at org.testng.SuiteRunner.runTest(SuiteRunner.java:437)
at org.testng.SuiteRunner.runSequentially(SuiteRunner.java:431)
at org.testng.SuiteRunner.privateRun(SuiteRunner.java:391)
at org.testng.SuiteRunner.run(SuiteRunner.java:330)
at org.testng.SuiteRunnerWorker.runSuite(SuiteRunnerWorker.java:52)
at org.testng.SuiteRunnerWorker.run(SuiteRunnerWorker.java:95)
at org.testng.TestNG.runSuitesSequentially(TestNG.java:1256)
at org.testng.TestNG.runSuitesLocally(TestNG.java:1176)
at org.testng.TestNG.runSuites(TestNG.java:1099)
at org.testng.TestNG.run(TestNG.java:1067)
at org.testng.remote.AbstractRemoteTestNG.run(AbstractRemoteTestNG.java:115)
at org.testng.remote.RemoteTestNG.initAndRun(RemoteTestNG.java:251)
at org.testng.remote.RemoteTestNG.main(RemoteTestNG.java:77)
]]>
            </full-stacktrace>
          </exception> <!-- java.lang.AssertionError -->
          <reporter-output>
          </reporter-output>
        </test-method> <!-- testLogin -->
        <test-method is-config="true" signature="generateTestStatus(java.lang.reflect.Method,org.testng.ITestResult)[pri:0, instance:Tests.LoginTest@38aa816f]" started-at="2023-12-01T16:04:10 IST" name="generateTestStatus" finished-at="2023-12-01T16:04:10 IST" duration-ms="1" status="PASS">
          <params>
            <param index="0">
              <value>
                <![CDATA[public void Tests.LoginTest.testLogin(java.lang.String,java.lang.String,java.lang.String)]]>
              </value>
            </param>
            <param index="1">
              <value>
                <![CDATA[[TestResult name=testLogin status=FAILURE method=LoginTest.testLogin(java.lang.String,java.lang.String,java.lang.String)[pri:1, instance:Tests.LoginTest@38aa816f] output={null}]]]>
              </value>
            </param>
          </params>
          <reporter-output>
          </reporter-output>
        </test-method> <!-- generateTestStatus -->
        <test-method signature="testLogin(java.lang.String,java.lang.String,java.lang.String)[pri:1, instance:Tests.LoginTest@38aa816f]" started-at="2023-12-01T16:04:10 IST" name="testLogin" data-provider="testdata" finished-at="2023-12-01T16:04:12 IST" duration-ms="1837" status="FAIL">
          <params>
            <param index="0">
              <value>
                <![CDATA[karthick1234554325@gmail.com]]>
              </value>
            </param>
            <param index="1">
              <value>
                <![CDATA["1234554321"]]>
              </value>
            </param>
            <param index="2">
              <value>
                <![CDATA[fail]]>
              </value>
            </param>
          </params>
          <exception class="java.lang.AssertionError">
            <message>
              <![CDATA[Login was unsuccessful. Error message is present.]]>
            </message>
            <full-stacktrace>
              <![CDATA[java.lang.AssertionError: Login was unsuccessful. Error message is present.
at org.testng.Assert.fail(Assert.java:110)
at Pages.LoginPage.login(LoginPage.java:40)
at Tests.LoginTest.testLogin(LoginTest.java:18)
at java.base/jdk.internal.reflect.DirectMethodHandleAccessor.invoke(DirectMethodHandleAccessor.java:104)
at java.base/java.lang.reflect.Method.invoke(Method.java:578)
at org.testng.internal.invokers.MethodInvocationHelper.invokeMethod(MethodInvocationHelper.java:139)
at org.testng.internal.invokers.TestInvoker.invokeMethod(TestInvoker.java:677)
at org.testng.internal.invokers.TestInvoker.invokeTestMethod(TestInvoker.java:221)
at org.testng.internal.invokers.MethodRunner.runInSequence(MethodRunner.java:50)
at org.testng.internal.invokers.TestInvoker$MethodInvocationAgent.invoke(TestInvoker.java:969)
at org.testng.internal.invokers.TestInvoker.invokeTestMethods(TestInvoker.java:194)
at org.testng.internal.invokers.TestMethodWorker.invokeTestMethods(TestMethodWorker.java:148)
at org.testng.internal.invokers.TestMethodWorker.run(TestMethodWorker.java:128)
at java.base/java.util.ArrayList.forEach(ArrayList.java:1511)
at org.testng.TestRunner.privateRun(TestRunner.java:829)
at org.testng.TestRunner.run(TestRunner.java:602)
at org.testng.SuiteRunner.runTest(SuiteRunner.java:437)
at org.testng.SuiteRunner.runSequentially(SuiteRunner.java:431)
at org.testng.SuiteRunner.privateRun(SuiteRunner.java:391)
at org.testng.SuiteRunner.run(SuiteRunner.java:330)
at org.testng.SuiteRunnerWorker.runSuite(SuiteRunnerWorker.java:52)
at org.testng.SuiteRunnerWorker.run(SuiteRunnerWorker.java:95)
at org.testng.TestNG.runSuitesSequentially(TestNG.java:1256)
at org.testng.TestNG.runSuitesLocally(TestNG.java:1176)
at org.testng.TestNG.runSuites(TestNG.java:1099)
at org.testng.TestNG.run(TestNG.java:1067)
at org.testng.remote.AbstractRemoteTestNG.run(AbstractRemoteTestNG.java:115)
at org.testng.remote.RemoteTestNG.initAndRun(RemoteTestNG.java:251)
at org.testng.remote.RemoteTestNG.main(RemoteTestNG.java:77)
]]>
            </full-stacktrace>
          </exception> <!-- java.lang.AssertionError -->
          <reporter-output>
          </reporter-output>
        </test-method> <!-- testLogin -->
        <test-method is-config="true" signature="generateTestStatus(java.lang.reflect.Method,org.testng.ITestResult)[pri:0, instance:Tests.LoginTest@38aa816f]" started-at="2023-12-01T16:04:12 IST" name="generateTestStatus" finished-at="2023-12-01T16:04:12 IST" duration-ms="2" status="PASS">
          <params>
            <param index="0">
              <value>
                <![CDATA[public void Tests.LoginTest.testLogin(java.lang.String,java.lang.String,java.lang.String)]]>
              </value>
            </param>
            <param index="1">
              <value>
                <![CDATA[[TestResult name=testLogin status=FAILURE method=LoginTest.testLogin(java.lang.String,java.lang.String,java.lang.String)[pri:1, instance:Tests.LoginTest@38aa816f] output={null}]]]>
              </value>
            </param>
          </params>
          <reporter-output>
          </reporter-output>
        </test-method> <!-- generateTestStatus -->
        <test-method signature="testLogin(java.lang.String,java.lang.String,java.lang.String)[pri:1, instance:Tests.LoginTest@38aa816f]" started-at="2023-12-01T16:04:12 IST" name="testLogin" data-provider="testdata" finished-at="2023-12-01T16:04:14 IST" duration-ms="1814" status="FAIL">
          <params>
            <param index="0">
              <value>
                <![CDATA[karthick1234554326@gmail.com]]>
              </value>
            </param>
            <param index="1">
              <value>
                <![CDATA["1234554321"]]>
              </value>
            </param>
            <param index="2">
              <value>
                <![CDATA[fail]]>
              </value>
            </param>
          </params>
          <exception class="java.lang.AssertionError">
            <message>
              <![CDATA[Login was unsuccessful. Error message is present.]]>
            </message>
            <full-stacktrace>
              <![CDATA[java.lang.AssertionError: Login was unsuccessful. Error message is present.
at org.testng.Assert.fail(Assert.java:110)
at Pages.LoginPage.login(LoginPage.java:40)
at Tests.LoginTest.testLogin(LoginTest.java:18)
at java.base/jdk.internal.reflect.DirectMethodHandleAccessor.invoke(DirectMethodHandleAccessor.java:104)
at java.base/java.lang.reflect.Method.invoke(Method.java:578)
at org.testng.internal.invokers.MethodInvocationHelper.invokeMethod(MethodInvocationHelper.java:139)
at org.testng.internal.invokers.TestInvoker.invokeMethod(TestInvoker.java:677)
at org.testng.internal.invokers.TestInvoker.invokeTestMethod(TestInvoker.java:221)
at org.testng.internal.invokers.MethodRunner.runInSequence(MethodRunner.java:50)
at org.testng.internal.invokers.TestInvoker$MethodInvocationAgent.invoke(TestInvoker.java:969)
at org.testng.internal.invokers.TestInvoker.invokeTestMethods(TestInvoker.java:194)
at org.testng.internal.invokers.TestMethodWorker.invokeTestMethods(TestMethodWorker.java:148)
at org.testng.internal.invokers.TestMethodWorker.run(TestMethodWorker.java:128)
at java.base/java.util.ArrayList.forEach(ArrayList.java:1511)
at org.testng.TestRunner.privateRun(TestRunner.java:829)
at org.testng.TestRunner.run(TestRunner.java:602)
at org.testng.SuiteRunner.runTest(SuiteRunner.java:437)
at org.testng.SuiteRunner.runSequentially(SuiteRunner.java:431)
at org.testng.SuiteRunner.privateRun(SuiteRunner.java:391)
at org.testng.SuiteRunner.run(SuiteRunner.java:330)
at org.testng.SuiteRunnerWorker.runSuite(SuiteRunnerWorker.java:52)
at org.testng.SuiteRunnerWorker.run(SuiteRunnerWorker.java:95)
at org.testng.TestNG.runSuitesSequentially(TestNG.java:1256)
at org.testng.TestNG.runSuitesLocally(TestNG.java:1176)
at org.testng.TestNG.runSuites(TestNG.java:1099)
at org.testng.TestNG.run(TestNG.java:1067)
at org.testng.remote.AbstractRemoteTestNG.run(AbstractRemoteTestNG.java:115)
at org.testng.remote.RemoteTestNG.initAndRun(RemoteTestNG.java:251)
at org.testng.remote.RemoteTestNG.main(RemoteTestNG.java:77)
]]>
            </full-stacktrace>
          </exception> <!-- java.lang.AssertionError -->
          <reporter-output>
          </reporter-output>
        </test-method> <!-- testLogin -->
        <test-method is-config="true" signature="generateTestStatus(java.lang.reflect.Method,org.testng.ITestResult)[pri:0, instance:Tests.LoginTest@38aa816f]" started-at="2023-12-01T16:04:14 IST" name="generateTestStatus" finished-at="2023-12-01T16:04:14 IST" duration-ms="3" status="PASS">
          <params>
            <param index="0">
              <value>
                <![CDATA[public void Tests.LoginTest.testLogin(java.lang.String,java.lang.String,java.lang.String)]]>
              </value>
            </param>
            <param index="1">
              <value>
                <![CDATA[[TestResult name=testLogin status=FAILURE method=LoginTest.testLogin(java.lang.String,java.lang.String,java.lang.String)[pri:1, instance:Tests.LoginTest@38aa816f] output={null}]]]>
              </value>
            </param>
          </params>
          <reporter-output>
          </reporter-output>
        </test-method> <!-- generateTestStatus -->
        <test-method signature="testLogin(java.lang.String,java.lang.String,java.lang.String)[pri:1, instance:Tests.LoginTest@38aa816f]" started-at="2023-12-01T16:04:14 IST" name="testLogin" data-provider="testdata" finished-at="2023-12-01T16:04:16 IST" duration-ms="2123" status="FAIL">
          <params>
            <param index="0">
              <value>
                <![CDATA[karthick1234554321@gmail.com]]>
              </value>
            </param>
            <param index="1">
              <value>
                <![CDATA[1.234554321E9]]>
              </value>
            </param>
            <param index="2">
              <value>
                <![CDATA[pass]]>
              </value>
            </param>
          </params>
          <exception class="java.lang.AssertionError">
            <message>
              <![CDATA[Login was unsuccessful. Error message is present.]]>
            </message>
            <full-stacktrace>
              <![CDATA[java.lang.AssertionError: Login was unsuccessful. Error message is present.
at org.testng.Assert.fail(Assert.java:110)
at Pages.LoginPage.login(LoginPage.java:40)
at Tests.LoginTest.testLogin(LoginTest.java:18)
at java.base/jdk.internal.reflect.DirectMethodHandleAccessor.invoke(DirectMethodHandleAccessor.java:104)
at java.base/java.lang.reflect.Method.invoke(Method.java:578)
at org.testng.internal.invokers.MethodInvocationHelper.invokeMethod(MethodInvocationHelper.java:139)
at org.testng.internal.invokers.TestInvoker.invokeMethod(TestInvoker.java:677)
at org.testng.internal.invokers.TestInvoker.invokeTestMethod(TestInvoker.java:221)
at org.testng.internal.invokers.MethodRunner.runInSequence(MethodRunner.java:50)
at org.testng.internal.invokers.TestInvoker$MethodInvocationAgent.invoke(TestInvoker.java:969)
at org.testng.internal.invokers.TestInvoker.invokeTestMethods(TestInvoker.java:194)
at org.testng.internal.invokers.TestMethodWorker.invokeTestMethods(TestMethodWorker.java:148)
at org.testng.internal.invokers.TestMethodWorker.run(TestMethodWorker.java:128)
at java.base/java.util.ArrayList.forEach(ArrayList.java:1511)
at org.testng.TestRunner.privateRun(TestRunner.java:829)
at org.testng.TestRunner.run(TestRunner.java:602)
at org.testng.SuiteRunner.runTest(SuiteRunner.java:437)
at org.testng.SuiteRunner.runSequentially(SuiteRunner.java:431)
at org.testng.SuiteRunner.privateRun(SuiteRunner.java:391)
at org.testng.SuiteRunner.run(SuiteRunner.java:330)
at org.testng.SuiteRunnerWorker.runSuite(SuiteRunnerWorker.java:52)
at org.testng.SuiteRunnerWorker.run(SuiteRunnerWorker.java:95)
at org.testng.TestNG.runSuitesSequentially(TestNG.java:1256)
at org.testng.TestNG.runSuitesLocally(TestNG.java:1176)
at org.testng.TestNG.runSuites(TestNG.java:1099)
at org.testng.TestNG.run(TestNG.java:1067)
at org.testng.remote.AbstractRemoteTestNG.run(AbstractRemoteTestNG.java:115)
at org.testng.remote.RemoteTestNG.initAndRun(RemoteTestNG.java:251)
at org.testng.remote.RemoteTestNG.main(RemoteTestNG.java:77)
]]>
            </full-stacktrace>
          </exception> <!-- java.lang.AssertionError -->
          <reporter-output>
          </reporter-output>
        </test-method> <!-- testLogin -->
        <test-method is-config="true" signature="generateTestStatus(java.lang.reflect.Method,org.testng.ITestResult)[pri:0, instance:Tests.LoginTest@38aa816f]" started-at="2023-12-01T16:04:16 IST" name="generateTestStatus" finished-at="2023-12-01T16:04:16 IST" duration-ms="2" status="PASS">
          <params>
            <param index="0">
              <value>
                <![CDATA[public void Tests.LoginTest.testLogin(java.lang.String,java.lang.String,java.lang.String)]]>
              </value>
            </param>
            <param index="1">
              <value>
                <![CDATA[[TestResult name=testLogin status=FAILURE method=LoginTest.testLogin(java.lang.String,java.lang.String,java.lang.String)[pri:1, instance:Tests.LoginTest@38aa816f] output={null}]]]>
              </value>
            </param>
          </params>
          <reporter-output>
          </reporter-output>
        </test-method> <!-- generateTestStatus -->
        <test-method is-config="true" signature="tearDown()[pri:0, instance:Tests.LoginTest@38aa816f]" started-at="2023-12-01T16:04:16 IST" name="tearDown" finished-at="2023-12-01T16:04:16 IST" duration-ms="412" status="PASS">
          <reporter-output>
          </reporter-output>
        </test-method> <!-- tearDown -->
        <test-method is-config="true" signature="generateReports()[pri:0, instance:Tests.LoginTest@38aa816f]" started-at="2023-12-01T16:04:17 IST" name="generateReports" finished-at="2023-12-01T16:04:18 IST" duration-ms="1093" status="PASS">
          <reporter-output>
          </reporter-output>
        </test-method> <!-- generateReports -->
      </class> <!-- Tests.LoginTest -->
    </test> <!-- Default test -->
  </suite> <!-- Default suite -->
</testng-results>
